<?xml version="1.0" encoding="UTF-8"?>
<testng-results skipped="0" failed="1" ignored="0" total="1" passed="0">
  <reporter-output>
  </reporter-output>
  <suite name="Failed suite [Default suite]" duration-ms="28135" started-at="2021-05-23T11:48:25Z" finished-at="2021-05-23T11:48:53Z">
    <groups>
    </groups>
    <test name="Default test(failed)" duration-ms="28135" started-at="2021-05-23T11:48:25Z" finished-at="2021-05-23T11:48:53Z">
      <class name="testscripts.log_in">
        <test-method status="PASS" signature="openapp()[pri:0, instance:testscripts.log_in@6f195bc3]" name="openapp" is-config="true" duration-ms="22534" started-at="2021-05-23T11:48:25Z" finished-at="2021-05-23T11:48:47Z">
          <reporter-output>
          </reporter-output>
        </test-method> <!-- openapp -->
        <test-method status="FAIL" signature="login_app()[pri:0, instance:testscripts.log_in@6f195bc3]" name="login_app" duration-ms="2374" started-at="2021-05-23T11:48:47Z" finished-at="2021-05-23T11:48:50Z">
          <exception class="java.lang.AssertionError">
            <message>
              <![CDATA[null]]>
            </message>
            <full-stacktrace>
              <![CDATA[java.lang.AssertionError: null
at org.testng.Assert.fail(Assert.java:96)
at org.testng.Assert.fail(Assert.java:103)
at testscripts.log_in.login_app(log_in.java:19)
at sun.reflect.NativeMethodAccessorImpl.invoke0(Native Method)
at sun.reflect.NativeMethodAccessorImpl.invoke(Unknown Source)
at sun.reflect.DelegatingMethodAccessorImpl.invoke(Unknown Source)
at java.lang.reflect.Method.invoke(Unknown Source)
at org.testng.internal.MethodInvocationHelper.invokeMethod(MethodInvocationHelper.java:124)
at org.testng.internal.Invoker.invokeMethod(Invoker.java:583)
at org.testng.internal.Invoker.invokeTestMethod(Invoker.java:719)
at org.testng.internal.Invoker.invokeTestMethods(Invoker.java:989)
at org.testng.internal.TestMethodWorker.invokeTestMethods(TestMethodWorker.java:125)
at org.testng.internal.TestMethodWorker.run(TestMethodWorker.java:109)
at org.testng.TestRunner.privateRun(TestRunner.java:648)
at org.testng.TestRunner.run(TestRunner.java:505)
at org.testng.SuiteRunner.runTest(SuiteRunner.java:455)
at org.testng.SuiteRunner.runSequentially(SuiteRunner.java:450)
at org.testng.SuiteRunner.privateRun(SuiteRunner.java:415)
at org.testng.SuiteRunner.run(SuiteRunner.java:364)
at org.testng.SuiteRunnerWorker.runSuite(SuiteRunnerWorker.java:52)
at org.testng.SuiteRunnerWorker.run(SuiteRunnerWorker.java:84)
at org.testng.TestNG.runSuitesSequentially(TestNG.java:1208)
at org.testng.TestNG.runSuitesLocally(TestNG.java:1137)
at org.testng.TestNG.runSuites(TestNG.java:1049)
at org.testng.TestNG.run(TestNG.java:1017)
at org.testng.remote.AbstractRemoteTestNG.run(AbstractRemoteTestNG.java:114)
at org.testng.remote.RemoteTestNG.initAndRun(RemoteTestNG.java:251)
at org.testng.remote.RemoteTestNG.main(RemoteTestNG.java:77)
]]>
            </full-stacktrace>
          </exception> <!-- java.lang.AssertionError -->
          <reporter-output>
          </reporter-output>
        </test-method> <!-- login_app -->
        <test-method status="PASS" signature="closeapp(org.testng.ITestResult)[pri:0, instance:testscripts.log_in@6f195bc3]" name="closeapp" is-config="true" duration-ms="3177" started-at="2021-05-23T11:48:50Z" finished-at="2021-05-23T11:48:53Z">
          <params>
            <param index="0">
              <value>
                <![CDATA[[TestResult name=login_app status=FAILURE method=log_in.login_app()[pri:0, instance:testscripts.log_in@6f195bc3] output={null}]]]>
              </value>
            </param>
          </params>
          <reporter-output>
          </reporter-output>
        </test-method> <!-- closeapp -->
      </class> <!-- testscripts.log_in -->
    </test> <!-- Default test(failed) -->
  </suite> <!-- Failed suite [Default suite] -->
</testng-results>
